<?xml version="1.0" ?>
<robot name="arc-bot-2">

  <material name="white">
    <color rgba="0.700 0.700 0.700 1.0"/>
  </material>
  <material name="dark">
    <color rgba="0.1 0.1 0.1 1.0"/>
  </material>
  <material name="metal">
    <color rgba="0.45 0.45 0.45 1.0"/>
  </material>
  <material name="blue">
    <color rgba="0.23 0.23 0.44 1.0"/>
  </material>

  <link name="base_link">
    <inertial>
      <origin xyz="5.959159644551385e-16 -8.513085206501979e-17 0.12187719245645033" rpy="0 0 0"/>
      <mass value="107.34771873814509"/>
      <inertia ixx="4.505164702504547" iyy="1.3309390396719774" izz="5.765242876816964" ixy="-5.445839279532476e-30" iyz="-1.1137872477797035e-15" ixz="3.0444372974824466e-15"/>
    </inertial>
    <visual>
      <origin xyz="0 0 0" rpy="-1.57079632679 0 0"/>
      <geometry>
        <mesh filename="meshes/base_link.stl" scale="0.001 0.001 0.001"/>
      </geometry>
      <material name="white"/>
      <material/>
    </visual>
    <collision>
      <origin xyz="0 0 0" rpy="-1.57079632679 0 0"/>
      <geometry>
        <mesh filename="meshes/base_link.stl" scale="0.001 0.001 0.001"/>
      </geometry>
    </collision>
  </link>

  <!-- DRIVE WHEELS -->

  <link name="drive_wheel_left">
    <inertial>
      <origin xyz="0.025000001258671342 8.399471678820184e-07 2.016479592729936e-05" rpy="0 0 0"/>
      <mass value="6.575317753803416"/>
      <inertia ixx="0.017576695509416068" iyy="0.010097567859487344" izz="0.010097543017547408" ixy="1.746670854310247e-11" iyz="1.8832109802272806e-08" ixz="1.4782201157581554e-09"/>
    </inertial>
    <visual>
      <origin xyz="-0.112 0.0 -0.075" rpy="-1.57079632679 0 0"/>
      <geometry>
        <mesh filename="meshes/drive_wheel2.stl" scale="0.001 0.001 0.001"/>
      </geometry>
      <material name="dark"/>
      <material/>
    </visual>
    <collision>
      <origin xyz="-0.112 0.0 -0.075" rpy="-1.57079632679 0 0"/>
      <geometry>
        <mesh filename="meshes/drive_wheel2.stl" scale="0.001 0.001 0.001"/>
      </geometry>
    </collision>
  </link>

  <link name="drive_wheel_right">
    <inertial>
      <origin xyz="-0.024999998741328702 8.399471678820184e-07 -1.9954997748997116e-05" rpy="0 0 0"/>
      <mass value="6.575317753803416"/>
      <inertia ixx="0.017576695509416068" iyy="0.010097567859487372" izz="0.01009754301754738" ixy="1.746670854320835e-11" iyz="1.8832109802272753e-08" ixz="1.478220143513731e-09"/>
    </inertial>
    <visual>
      <origin xyz="0.112 0.0 -0.075" rpy="-1.57079632679 0 0"/>
      <geometry>
        <mesh filename="meshes/drive_wheel1.stl" scale="0.001 0.001 0.001"/>
      </geometry>
      <material name="dark"/>
      <material/>
    </visual>
    <collision>
      <origin xyz="0.112 0.0 -0.075" rpy="-1.57079632679 0 0"/>
      <geometry>
        <mesh filename="meshes/drive_wheel1.stl" scale="0.001 0.001 0.001"/>
      </geometry>
    </collision>
  </link>

  <!-- CASTER WHEELS -->

  <link name="caster_bracket_fl">
    <inertial>
      <origin xyz="-8.493206138382448e-15 0.010475317633716452 -0.02267541961025038" rpy="0 0 0"/>
      <mass value="0.16207930958391914"/>
      <inertia ixx="9.076311533944524e-05" iyy="6.70912859518898e-05" izz="6.081469735370881e-05" ixy="-1.3877787807814457e-17" iyz="2.600926877512153e-05" ixz="2.862293735361732e-17"/>
    </inertial>
    <visual>
      <origin xyz="-0.15 0.3 -0.105" rpy="-1.57079632679 0 0"/>
      <geometry>
        <mesh filename="meshes/simple_caster_bracket_v51.stl" scale="0.001 0.001 0.001"/>
      </geometry>
      <material name="dark"/>
      <material/>
    </visual>
    <!-- <collision>
    <origin xyz="-0.15 0.3 -0.105" rpy="-1.57079632679 0 0"/>
    <geometry>
      <mesh filename="meshes/simple_caster_bracket_v51.stl" scale="0.001 0.001 0.001"/>
    </geometry>
  </collision> -->
  </link>

  <link name="caster_wheel_fl">
    <inertial>
      <origin xyz="-0.1599999998360872 0.3 -0.1" rpy="0 0 0"/>
      <mass value="0.670125387642777"/>
      <inertia ixx="0.0004554214921724045" iyy="0.00024968084295089177" izz="0.00024968084295089177" ixy="-3.469446951953614e-18" iyz="8.673617379884035e-19" ixz="-4.336808689942018e-19"/>
    </inertial>
    <visual>
      <origin xyz="0.011 0 0" rpy="0 0 0"/>
      <geometry>
        <mesh filename="meshes/simepl_caster_wheel_clean.stl" scale="0.001 0.001 0.001"/>
      </geometry>
      <material name="blue"/>
      <material/>
    </visual>
    <collision>
      <origin xyz="0.011 0 0" rpy="0 0 0"/>
      <geometry>
        <mesh filename="meshes/simepl_caster_wheel_clean.stl" scale="0.001 0.001 0.001"/>
      </geometry>
    </collision>
  </link>

  <link name="caster_bracket_fr">
    <inertial>
      <origin xyz="-8.493206138382448e-15 0.010475317633716452 -0.02267541961025038" rpy="0 0 0"/>
      <mass value="0.16207930958391914"/>
      <inertia ixx="9.076311533944524e-05" iyy="6.70912859518898e-05" izz="6.081469735370881e-05" ixy="-1.3877787807814457e-17" iyz="2.600926877512153e-05" ixz="2.862293735361732e-17"/>
    </inertial>
    <visual>
      <origin xyz="-0.15 0.3 -0.105" rpy="-1.57079632679 0 0"/>
      <geometry>
        <mesh filename="meshes/simple_caster_bracket_v51.stl" scale="0.001 0.001 0.001"/>
      </geometry>
      <material name="dark"/>
      <material/>
    </visual>
    <!-- <collision>
    <origin xyz="-0.15 0.3 -0.105" rpy="-1.57079632679 0 0"/>
    <geometry>
      <mesh filename="meshes/simple_caster_bracket_v51.stl" scale="0.001 0.001 0.001"/>
    </geometry>
  </collision> -->
  </link>

  <link name="caster_wheel_fr">
    <inertial>
      <origin xyz="-0.1599999998360872 0.3 -0.1" rpy="0 0 0"/>
      <mass value="0.670125387642777"/>
      <inertia ixx="0.0004554214921724045" iyy="0.00024968084295089177" izz="0.00024968084295089177" ixy="-3.469446951953614e-18" iyz="8.673617379884035e-19" ixz="-4.336808689942018e-19"/>
    </inertial>
    <visual>
      <origin xyz="-0.011 0 0" rpy="0 0 0"/>
      <geometry>
        <mesh filename="meshes/simepl_caster_wheel_clean.stl" scale="0.001 0.001 0.001"/>
      </geometry>
      <material name="blue"/>
      <material/>
    </visual>
    <collision>
      <origin xyz="0.011 0 0" rpy="0 0 0"/>
      <geometry>
        <mesh filename="meshes/simepl_caster_wheel_clean.stl" scale="0.001 0.001 0.001"/>
      </geometry>
    </collision>
  </link>

  <link name="caster_bracket_bl">
    <inertial>
      <origin xyz="-8.493206138382448e-15 0.010475317633716452 -0.02267541961025038" rpy="0 0 0"/>
      <mass value="0.16207930958391914"/>
      <inertia ixx="9.076311533944524e-05" iyy="6.70912859518898e-05" izz="6.081469735370881e-05" ixy="-1.3877787807814457e-17" iyz="2.600926877512153e-05" ixz="2.862293735361732e-17"/>
    </inertial>
    <visual>
      <origin xyz="-0.15 0.3 -0.105" rpy="-1.57079632679 0 0"/>
      <geometry>
        <mesh filename="meshes/simple_caster_bracket_v51.stl" scale="0.001 0.001 0.001"/>
      </geometry>
      <material name="dark"/>
      <material/>
    </visual>
    <!-- <collision>
    <origin xyz="-0.15 0.3 -0.105" rpy="-1.57079632679 0 0"/>
    <geometry>
      <mesh filename="meshes/simple_caster_bracket_v51.stl" scale="0.001 0.001 0.001"/>
    </geometry>
  </collision> -->
  </link>

  <link name="caster_wheel_bl">
    <inertial>
      <origin xyz="-0.1599999998360872 0.3 -0.1" rpy="0 0 0"/>
      <mass value="0.670125387642777"/>
      <inertia ixx="0.0004554214921724045" iyy="0.00024968084295089177" izz="0.00024968084295089177" ixy="-3.469446951953614e-18" iyz="8.673617379884035e-19" ixz="-4.336808689942018e-19"/>
    </inertial>
    <visual>
      <origin xyz="0.011 0 0" rpy="0 0 0"/>
      <geometry>
        <mesh filename="meshes/simepl_caster_wheel_clean.stl" scale="0.001 0.001 0.001"/>
      </geometry>
      <material name="blue"/>
      <material/>
    </visual>
    <collision>
      <origin xyz="0.011 0 0" rpy="0 0 0"/>
      <geometry>
        <mesh filename="meshes/simepl_caster_wheel_clean.stl" scale="0.001 0.001 0.001"/>
      </geometry>
    </collision>
  </link>

  <link name="caster_bracket_br">
    <inertial>
      <origin xyz="-8.493206138382448e-15 0.010475317633716452 -0.02267541961025038" rpy="0 0 0"/>
      <mass value="0.16207930958391914"/>
      <inertia ixx="9.076311533944524e-05" iyy="6.70912859518898e-05" izz="6.081469735370881e-05" ixy="-1.3877787807814457e-17" iyz="2.600926877512153e-05" ixz="2.862293735361732e-17"/>
    </inertial>
    <visual>
      <origin xyz="-0.15 0.3 -0.105" rpy="-1.57079632679 0 0"/>
      <geometry>
        <mesh filename="meshes/simple_caster_bracket_v51.stl" scale="0.001 0.001 0.001"/>
      </geometry>
      <material name="dark"/>
      <material/>
    </visual>
    <!-- <collision>
    <origin xyz="-0.15 0.3 -0.105" rpy="-1.57079632679 0 0"/>
    <geometry>
      <mesh filename="meshes/simple_caster_bracket_v51.stl" scale="0.001 0.001 0.001"/>
    </geometry>
  </collision> -->
  </link>

  <link name="caster_wheel_br">
    <inertial>
      <origin xyz="-0.1599999998360872 0.3 -0.1" rpy="0 0 0"/>
      <mass value="0.670125387642777"/>
      <inertia ixx="0.0004554214921724045" iyy="0.00024968084295089177" izz="0.00024968084295089177" ixy="-3.469446951953614e-18" iyz="8.673617379884035e-19" ixz="-4.336808689942018e-19"/>
    </inertial>
    <visual>
      <origin xyz="-0.011 0 0" rpy="0 0 0"/>
      <geometry>
        <mesh filename="meshes/simepl_caster_wheel_clean.stl" scale="0.001 0.001 0.001"/>
      </geometry>
      <material name="blue"/>
      <material/>
    </visual>
    <collision>
      <origin xyz="0.011 0 0" rpy="0 0 0"/>
      <geometry>
        <mesh filename="meshes/simepl_caster_wheel_clean.stl" scale="0.001 0.001 0.001"/>
      </geometry>
    </collision>
  </link>

  <!-- DRIVE JOINTS -->

  <joint name="Revolute_left" type="continuous">
    <origin xyz="0.112 0.0 0.075" rpy="0 0 0"/>
    <parent link="base_link"/>
    <child link="drive_wheel_left"/>
    <axis xyz="1.0 0.0 0.0"/>
  </joint>
  <transmission name="Revolute_left_tran">
    <type>transmission_interface/SimpleTransmission</type>
    <joint name="Revolute_left">
      <hardwareInterface>PositionJointInterface</hardwareInterface>
    </joint>
    <actuator name="Revolute_left_actr">
      <hardwareInterface>PositionJointInterface</hardwareInterface>
      <mechanicalReduction>1</mechanicalReduction>
    </actuator>
  </transmission>

  <joint name="Revolute_right" type="continuous">
    <origin xyz="-0.112 0.0 0.075" rpy="0 0 0"/>
    <parent link="base_link"/>
    <child link="drive_wheel_right"/>
    <axis xyz="-1.0 0.0 0.0"/>
  </joint>
  <transmission name="Revolute_right_tran">
    <type>transmission_interface/SimpleTransmission</type>
    <joint name="Revolute_right">
      <hardwareInterface>PositionJointInterface</hardwareInterface>
    </joint>
    <actuator name="Revolute_right_actr">
      <hardwareInterface>PositionJointInterface</hardwareInterface>
      <mechanicalReduction>1</mechanicalReduction>
    </actuator>
  </transmission>

  <!-- CASTER JOINTS -->

  <joint name="Revolute_caster_fl" type="continuous">
    <origin xyz="0.15 -0.3 0.105" rpy="0 0 0"/>
    <parent link="base_link"/>
    <child link="caster_bracket_fl"/>
    <axis xyz="0.0 0.0 -1.0"/>
  </joint>
  <transmission name="Revolute_caster_fl_tran">
    <type>transmission_interface/SimpleTransmission</type>
    <joint name="Revolute_caster_fl">
      <hardwareInterface>PositionJointInterface</hardwareInterface>
    </joint>
    <actuator name="Revolute_caster_fl_actr">
      <hardwareInterface>PositionJointInterface</hardwareInterface>
      <mechanicalReduction>1</mechanicalReduction>
    </actuator>
  </transmission>

  <joint name="Revolute_caster_wheel_fl" type="continuous">
    <origin xyz="-0.011 0.0345 -0.0725" rpy="0 0 0"/>
    <parent link="caster_bracket_fl"/>
    <child link="caster_wheel_fl"/>
    <axis xyz="-1.0 0.0 0.0"/>
  </joint>
  <transmission name="Revolute_caster_wheel_fl_tran">
    <type>transmission_interface/SimpleTransmission</type>
    <joint name="Revolute_caster_wheel_fl">
      <hardwareInterface>PositionJointInterface</hardwareInterface>
    </joint>
    <actuator name="Revolute_caster_wheel_fl_actr">
      <hardwareInterface>PositionJointInterface</hardwareInterface>
      <mechanicalReduction>1</mechanicalReduction>
    </actuator>
  </transmission>

  <joint name="Revolute_caster_fr" type="continuous">
    <origin xyz="-0.15 -0.3 0.105" rpy="0 0 0"/>
    <parent link="base_link"/>
    <child link="caster_bracket_fr"/>
    <axis xyz="0.0 0.0 -1.0"/>
  </joint>
  <transmission name="Revolute_caster_fr_tran">
    <type>transmission_interface/SimpleTransmission</type>
    <joint name="Revolute_caster_fr">
      <hardwareInterface>PositionJointInterface</hardwareInterface>
    </joint>
    <actuator name="Revolute_caster_fr_actr">
      <hardwareInterface>PositionJointInterface</hardwareInterface>
      <mechanicalReduction>1</mechanicalReduction>
    </actuator>
  </transmission>

  <joint name="Revolute_caster_wheel_fr" type="continuous">
    <origin xyz="0.011 0.0345 -0.0725" rpy="0 0 0"/>
    <parent link="caster_bracket_fr"/>
    <child link="caster_wheel_fr"/>
    <axis xyz="-1.0 0.0 0.0"/>
  </joint>
  <transmission name="Revolute_caster_wheel_fr_tran">
    <type>transmission_interface/SimpleTransmission</type>
    <joint name="Revolute_caster_wheel_fr">
      <hardwareInterface>PositionJointInterface</hardwareInterface>
    </joint>
    <actuator name="Revolute_caster_wheel_fr_actr">
      <hardwareInterface>PositionJointInterface</hardwareInterface>
      <mechanicalReduction>1</mechanicalReduction>
    </actuator>
  </transmission>

  <joint name="Revolute_caster_bl" type="continuous">
    <origin xyz="0.15 0.3 0.105" rpy="0 0 0"/>
    <parent link="base_link"/>
    <child link="caster_bracket_bl"/>
    <axis xyz="0.0 0.0 -1.0"/>
  </joint>
  <transmission name="Revolute_caster_bl_tran">
    <type>transmission_interface/SimpleTransmission</type>
    <joint name="Revolute_caster_bl">
      <hardwareInterface>PositionJointInterface</hardwareInterface>
    </joint>
    <actuator name="Revolute_caster_bl_actr">
      <hardwareInterface>PositionJointInterface</hardwareInterface>
      <mechanicalReduction>1</mechanicalReduction>
    </actuator>
  </transmission>

  <joint name="Revolute_caster_wheel_bl" type="continuous">
    <origin xyz="-0.011 0.0345 -0.0725" rpy="0 0 0"/>
    <parent link="caster_bracket_bl"/>
    <child link="caster_wheel_bl"/>
    <axis xyz="-1.0 0.0 0.0"/>
  </joint>
  <transmission name="Revolute_caster_wheel_bl_tran">
    <type>transmission_interface/SimpleTransmission</type>
    <joint name="Revolute_caster_wheel_bl">
      <hardwareInterface>PositionJointInterface</hardwareInterface>
    </joint>
    <actuator name="Revolute_caster_wheel_bl_actr">
      <hardwareInterface>PositionJointInterface</hardwareInterface>
      <mechanicalReduction>1</mechanicalReduction>
    </actuator>
  </transmission>

  <joint name="Revolute_caster_br" type="continuous">
    <origin xyz="-0.15 0.3 0.105" rpy="0 0 0"/>
    <parent link="base_link"/>
    <child link="caster_bracket_br"/>
    <axis xyz="0.0 0.0 -1.0"/>
  </joint>
  <transmission name="Revolute_caster_br_tran">
    <type>transmission_interface/SimpleTransmission</type>
    <joint name="Revolute_caster_br">
      <hardwareInterface>PositionJointInterface</hardwareInterface>
    </joint>
    <actuator name="Revolute_caster_br_actr">
      <hardwareInterface>PositionJointInterface</hardwareInterface>
      <mechanicalReduction>1</mechanicalReduction>
    </actuator>
  </transmission>

  <joint name="Revolute_caster_wheel_br" type="continuous">
    <origin xyz="0.011 0.0345 -0.0725" rpy="0 0 0"/>
    <parent link="caster_bracket_br"/>
    <child link="caster_wheel_br"/>
    <axis xyz="-1.0 0.0 0.0"/>
  </joint>
  <transmission name="Revolute_caster_wheel_br_tran">
    <type>transmission_interface/SimpleTransmission</type>
    <joint name="Revolute_caster_wheel_br">
      <hardwareInterface>PositionJointInterface</hardwareInterface>
    </joint>
    <actuator name="Revolute_caster_wheel_br_actr">
      <hardwareInterface>PositionJointInterface</hardwareInterface>
      <mechanicalReduction>1</mechanicalReduction>
    </actuator>
  </transmission>

</robot>
